#usda 1.0
(
    defaultPrim = "Robotiq_2F_85"
    subLayers = [
        @Physics.usda@
    ]
    endTimeCode = 0
    metersPerUnit = 1
    startTimeCode = -1
    upAxis = "Z"
)

    over "Robotiq_2F_85" (
        prepend apiSchemas = ["PhysxArticulationAPI"]
    )
    {
        bool physxArticulation:enabledSelfCollisions = 0

        over "Joints"
        {
            def PhysicsRevoluteJoint "finger_joint" (
                prepend apiSchemas = ["PhysxJointAPI", "PhysicsDriveAPI:angular", "PhysicsJointStateAPI:angular"]
            )
            {
                float drive:angular:physics:damping = 0.0002
                float drive:angular:physics:maxForce = 16.5
                float drive:angular:physics:stiffness = 0.17
                float drive:angular:physics:targetPosition = 0
                float drive:angular:physics:targetVelocity = 0
                token physics:axis = "Z"
                custom rel physics:body0
                prepend rel physics:body0 = </Robotiq_2F_85/base_link>
                custom rel physics:body1
                prepend rel physics:body1 = </Robotiq_2F_85/left_outer_knuckle>
                point3f physics:localPos0 = (0, -0.0306, 0.05466)
                point3f physics:localPos1 = (0, -0.0306, 0.05466)
                quatf physics:localRot0 = (0.5, 0.5, -0.5, -0.5)
                quatf physics:localRot1 = (0.5, 0.5, -0.5, -0.5)
                float physics:lowerLimit = 0
                float physics:upperLimit = 75
                float physxJoint:maxJointVelocity = 130
                float state:angular:physics:position = 0
                float state:angular:physics:velocity = 0
            }

            def PhysicsRevoluteJoint "right_outer_knuckle_joint" (
                delete apiSchemas = ["PhysicsDriveAPI:angular"]
                prepend apiSchemas = ["PhysxJointAPI", "PhysxMimicJointAPI:rotZ", "PhysicsJointStateAPI:angular"]
            )
            {
                float drive:angular:physics:damping = 5000
                float drive:angular:physics:maxForce = 5
                float drive:angular:physics:stiffness = 0
                token physics:axis = "Z"
                custom rel physics:body0
                prepend rel physics:body0 = </Robotiq_2F_85/base_link>
                custom rel physics:body1
                prepend rel physics:body1 = </Robotiq_2F_85/right_outer_knuckle>
                point3f physics:localPos0 = (0, 0.0306, 0.05466)
                point3f physics:localPos1 = (0, 0.0306, 0.05466)
                quatf physics:localRot0 = (0.5, 0.5, 0.5, 0.5)
                quatf physics:localRot1 = (0.5, 0.5, 0.5, 0.5)
                float physics:lowerLimit = 0
                float physics:upperLimit = 75
                float physxJoint:maxJointVelocity = 130
                float physxMimicJoint:rotZ:dampingRatio = 0.01
                float physxMimicJoint:rotZ:gearing = -1
                float physxMimicJoint:rotZ:naturalFrequency = 5000
                custom rel physxMimicJoint:rotZ:referenceJoint
                prepend rel physxMimicJoint:rotZ:referenceJoint = </Robotiq_2F_85/Joints/finger_joint>
                float state:angular:physics:position = 0
                float state:angular:physics:velocity = 0
            }

            def PhysicsRevoluteJoint "right_outer_finger_joint" (
                prepend apiSchemas = ["PhysicsDriveAPI:angular", "PhysicsJointStateAPI:angular"]
            )
            {
                float drive:angular:physics:damping = 0
                float drive:angular:physics:stiffness = 0
                token physics:axis = "Z"
                custom rel physics:body0
                prepend rel physics:body0 = </Robotiq_2F_85/right_outer_knuckle>
                custom rel physics:body1
                prepend rel physics:body1 = </Robotiq_2F_85/right_outer_finger>
                point3f physics:localPos0 = (0, 0.06213, 0.0509)
                point3f physics:localPos1 = (0, 0.06213, 0.0509)
                quatf physics:localRot0 = (0.5, 0.5, 0.5, 0.5)
                quatf physics:localRot1 = (0.5, 0.5, 0.5, 0.5)
                float physics:lowerLimit = 0
                float physics:upperLimit = 180
                float state:angular:physics:position = 0
                float state:angular:physics:velocity = 0
            }

            def PhysicsRevoluteJoint "right_inner_finger_joint" (
                prepend apiSchemas = ["PhysicsDriveAPI:angular", "PhysicsJointStateAPI:angular"]
            )
            {
                float drive:angular:physics:damping = 0.00001
                float drive:angular:physics:maxForce = 0.5
                float drive:angular:physics:stiffness = 0.0002
                float drive:angular:physics:targetPosition = 45
                token physics:axis = "Z"
                custom rel physics:body0
                prepend rel physics:body0 = </Robotiq_2F_85/right_outer_finger>
                custom rel physics:body1
                prepend rel physics:body1 = </Robotiq_2F_85/right_inner_finger>
                point3f physics:localPos0 = (0, 0.06776, 0.09809)
                point3f physics:localPos1 = (0, 0.06776, 0.09809)
                quatf physics:localRot0 = (0.5, 0.5, 0.5, 0.5)
                quatf physics:localRot1 = (0.5, 0.5, 0.5, 0.5)
                float physics:lowerLimit = -inf
                float physics:upperLimit = inf
                float state:angular:physics:position = 0
                float state:angular:physics:velocity = 0
            }

            def PhysicsRevoluteJoint "right_inner_knuckle_joint" (
                prepend apiSchemas = ["PhysicsDriveAPI:angular", "PhysicsJointStateAPI:angular"]
            )
            {
                float drive:angular:physics:damping = 0
                float drive:angular:physics:stiffness = 0
                token physics:axis = "Z"
                custom rel physics:body0
                prepend rel physics:body0 = </Robotiq_2F_85/base_link>
                custom rel physics:body1
                prepend rel physics:body1 = </Robotiq_2F_85/right_inner_knuckle>
                bool physics:excludeFromArticulation = 1
                point3f physics:localPos0 = (0, 0.0127, 0.06118)
                point3f physics:localPos1 = (0, 0.0127, 0.06118)
                quatf physics:localRot0 = (0.5, 0.5, 0.5, 0.5)
                quatf physics:localRot1 = (0.5, 0.5, 0.5, 0.5)
                float physics:lowerLimit = -inf
                float physics:upperLimit = inf
            }

            def PhysicsRevoluteJoint "right_inner_finger_knuckle_joint" (
                prepend apiSchemas = ["PhysicsDriveAPI:angular", "PhysicsJointStateAPI:angular"]
            )
            {
                float drive:angular:physics:damping = 0
                float drive:angular:physics:stiffness = 0
                token physics:axis = "Z"
                custom rel physics:body0
                prepend rel physics:body0 = </Robotiq_2F_85/right_inner_finger>
                custom rel physics:body1
                prepend rel physics:body1 = </Robotiq_2F_85/right_inner_knuckle>
                point3f physics:localPos0 = (0, 0.04986, 0.1046)
                point3f physics:localPos1 = (0, 0.04986, 0.1046)
                quatf physics:localRot0 = (0.5, 0.5, 0.5, 0.5)
                quatf physics:localRot1 = (0.5, 0.5, 0.5, 0.5)
                float state:angular:physics:position = 0
                float state:angular:physics:velocity = 0
            }

            def PhysicsRevoluteJoint "left_outer_finger_joint" (
                prepend apiSchemas = ["PhysicsDriveAPI:angular", "PhysicsJointStateAPI:angular"]
            )
            {
                float drive:angular:physics:damping = 0
                float drive:angular:physics:stiffness = 0
                token physics:axis = "Z"
                custom rel physics:body0
                prepend rel physics:body0 = </Robotiq_2F_85/left_outer_knuckle>
                custom rel physics:body1
                prepend rel physics:body1 = </Robotiq_2F_85/left_outer_finger>
                point3f physics:localPos0 = (0, -0.06213, 0.0509)
                point3f physics:localPos1 = (0, -0.06213, 0.0509)
                quatf physics:localRot0 = (0.5, 0.5, 0.5, 0.5)
                quatf physics:localRot1 = (0.5, 0.5, 0.5, 0.5)
                float physics:lowerLimit = 0
                float physics:upperLimit = 180
                float state:angular:physics:position = 0
                float state:angular:physics:velocity = 0
            }

            def PhysicsRevoluteJoint "left_inner_finger_knuckle_joint" (
                prepend apiSchemas = ["PhysicsDriveAPI:angular", "PhysicsJointStateAPI:angular"]
            )
            {
                float drive:angular:physics:damping = 0
                float drive:angular:physics:stiffness = 0
                token physics:axis = "Z"
                custom rel physics:body0
                prepend rel physics:body0 = </Robotiq_2F_85/left_inner_finger>
                custom rel physics:body1
                prepend rel physics:body1 = </Robotiq_2F_85/left_inner_knuckle>
                point3f physics:localPos0 = (0, -0.04986, 0.1046)
                point3f physics:localPos1 = (0, -0.04986, 0.1046)
                quatf physics:localRot0 = (0.5, 0.5, 0.5, 0.5)
                quatf physics:localRot1 = (0.5, 0.5, 0.5, 0.5)
                float physics:lowerLimit = -inf
                float physics:upperLimit = inf
                float state:angular:physics:position = 0
                float state:angular:physics:velocity = 0
            }

            def PhysicsRevoluteJoint "left_inner_finger_joint" (
                prepend apiSchemas = ["PhysicsDriveAPI:angular", "PhysicsJointStateAPI:angular"]
            )
            {
                float drive:angular:physics:damping = 0.00001
                float drive:angular:physics:maxForce = 0.5
                float drive:angular:physics:stiffness = 0.0002
                float drive:angular:physics:targetPosition = 45
                token physics:axis = "Z"
                custom rel physics:body0
                prepend rel physics:body0 = </Robotiq_2F_85/left_outer_finger>
                custom rel physics:body1
                prepend rel physics:body1 = </Robotiq_2F_85/left_inner_finger>
                point3f physics:localPos0 = (0, -0.06776, 0.09809)
                point3f physics:localPos1 = (0, -0.06776, 0.09809)
                quatf physics:localRot0 = (0.5, 0.5, 0.5, 0.5)
                quatf physics:localRot1 = (0.5, 0.5, 0.5, 0.5)
                float physics:lowerLimit = -inf
                float physics:upperLimit = inf
                float state:angular:physics:position = 0
                float state:angular:physics:velocity = 0
            }

            def PhysicsRevoluteJoint "left_inner_knuckle_joint" (
                prepend apiSchemas = ["PhysicsDriveAPI:angular", "PhysicsJointStateAPI:angular"]
            )
            {
                float drive:angular:physics:damping = 0
                float drive:angular:physics:stiffness = 0
                token physics:axis = "Z"
                custom rel physics:body0
                prepend rel physics:body0 = </Robotiq_2F_85/base_link>
                custom rel physics:body1
                prepend rel physics:body1 = </Robotiq_2F_85/left_inner_knuckle>
                bool physics:excludeFromArticulation = 1
                point3f physics:localPos0 = (0, -0.0127, 0.06118)
                point3f physics:localPos1 = (0, -0.0127, 0.06118)
                quatf physics:localRot0 = (0.5, 0.5, 0.5, 0.5)
                quatf physics:localRot1 = (0.5, 0.5, 0.5, 0.5)
                float physics:lowerLimit = -inf
                float physics:upperLimit = inf
            }
        }
    }
